<robot
  name="three_link">
  <link
    name="base_link">
    <inertial>
      <origin
        xyz="-0.017301 0 -0.005"
        rpy="0 0 0" />
      <mass
        value="0.014671" />
      <inertia
        ixx="8.9917E-07"
        ixy="1.5212E-22"
        ixz="2.5849E-23"
        iyy="3.9977E-06"
        iyz="-2.2058E-24"
        izz="4.6523E-06" />
    </inertial>
    <visual>
      <origin
        xyz="0 0 0"
        rpy="0 0 0" />
      <geometry>
        <mesh
          filename="package://three_link/meshes/base_link.STL" />
      </geometry>
      <material
        name="">
        <color
          rgba="1 1 1 1" />
      </material>
    </visual>
    <collision>
      <origin
        xyz="0 0 0"
        rpy="0 0 0" />
      <geometry>
        <mesh
          filename="package://three_link/meshes/base_link.STL" />
      </geometry>
    </collision>
  </link>
  <link
    name="link1">
    <inertial>
      <origin
        xyz="-0.017301 0 -0.005"
        rpy="0 0 0" />
      <mass
        value="0.014671" />
      <inertia
        ixx="8.9917E-07"
        ixy="1.5212E-22"
        ixz="2.5849E-23"
        iyy="3.9977E-06"
        iyz="-2.8595E-24"
        izz="4.6523E-06" />
    </inertial>
    <visual>
      <origin
        xyz="0 0 0"
        rpy="0 0 0" />
      <geometry>
        <mesh
          filename="package://three_link/meshes/link1.STL" />
      </geometry>
      <material
        name="">
        <color
          rgba="1 1 1 1" />
      </material>
    </visual>
    <collision>
      <origin
        xyz="0 0 0"
        rpy="0 0 0" />
      <geometry>
        <mesh
          filename="package://three_link/meshes/link1.STL" />
      </geometry>
    </collision>
  </link>
  <joint
    name="joint1"
    type="revolute">
    <origin
      xyz="-0.034603 0 0.01"
      rpy="0 0 0" />
    <parent
      link="base_link" />
    <child
      link="link1" />
    <axis
      xyz="0 0 -1" />
    <limit
      lower="-1.57"
      upper="1.57"
      effort="0"
      velocity="0" />
  </joint>
  <link
    name="link2">
    <inertial>
      <origin
        xyz="-0.017301 -6.9389E-18 -0.005"
        rpy="0 0 0" />
      <mass
        value="0.014671" />
      <inertia
        ixx="8.9917E-07"
        ixy="1.5212E-22"
        ixz="2.5849E-23"
        iyy="3.9977E-06"
        iyz="-2.7123E-23"
        izz="4.6523E-06" />
    </inertial>
    <visual>
      <origin
        xyz="0 0 0"
        rpy="0 0 0" />
      <geometry>
        <mesh
          filename="package://three_link/meshes/link2.STL" />
      </geometry>
      <material
        name="">
        <color
          rgba="1 1 1 1" />
      </material>
    </visual>
    <collision>
      <origin
        xyz="0 0 0"
        rpy="0 0 0" />
      <geometry>
        <mesh
          filename="package://three_link/meshes/link2.STL" />
      </geometry>
    </collision>
  </link>
  <joint
    name="joint2"
    type="revolute">
    <origin
      xyz="-0.034603 0 0.01"
      rpy="0 0 0" />
    <parent
      link="link1" />
    <child
      link="link2" />
    <axis
      xyz="0 0 -1" />
    <limit
      lower="-1.57"
      upper="1.57"
      effort="0"
      velocity="0" />
  </joint>
</robot>